{
  "Header": {
    "Original": "CVE-2025-59682 (An issue was discovered in Django 4.2 before 4.2.25, 5.1 before 5.1.13 ...)",
    "ID": "CVE-2025-59682",
    "Description": "(An issue was discovered in Django 4.2 before 4.2.25, 5.1 before 5.1.13 ...)"
  },
  "Annotations": [
    {
      "Original": "{DLA-4324-1}",
      "Type": "xref",
      "Bugs": [
        "DLA-4324-1"
      ]
    },
    {
      "Original": "- python-django 3:4.2.25-1 (bug #1116979)",
      "Type": "package",
      "Package": "python-django",
      "Kind": "fixed",
      "Version": "3:4.2.25-1",
      "BugNo": 1116979
    },
    {
      "Original": "NOTE: https://www.djangoproject.com/weblog/2025/oct/01/security-releases/",
      "Type": "NOTE",
      "Description": "https://www.djangoproject.com/weblog/2025/oct/01/security-releases/"
    },
    {
      "Original": "NOTE: https://github.com/django/django/commit/9504bbaa392c9fe37eee9291f5b4c29eb6037619 (4.2.25)",
      "Type": "NOTE",
      "Description": "https://github.com/django/django/commit/9504bbaa392c9fe37eee9291f5b4c29eb6037619 (4.2.25)"
    }
  ]
}