{
  "Header": {
    "Original": "CVE-2025-3730 (A vulnerability, which was classified as problematic, was found in PyT ...)",
    "ID": "CVE-2025-3730",
    "Description": "(A vulnerability, which was classified as problematic, was found in PyT ...)"
  },
  "Annotations": [
    {
      "Original": "- pytorch \u003cunfixed\u003e (bug #1103455)",
      "Type": "package",
      "Package": "pytorch",
      "Kind": "unfixed",
      "BugNo": 1103455
    },
    {
      "Original": "[trixie] - pytorch \u003cno-dsa\u003e (Minor issue)",
      "Type": "package",
      "Release": "trixie",
      "Package": "pytorch",
      "Kind": "no-dsa",
      "Description": "Minor issue"
    },
    {
      "Original": "[bookworm] - pytorch \u003cno-dsa\u003e (Minor issue)",
      "Type": "package",
      "Release": "bookworm",
      "Package": "pytorch",
      "Kind": "no-dsa",
      "Description": "Minor issue"
    },
    {
      "Original": "[bullseye] - pytorch \u003cpostponed\u003e (Minor issue; DoS)",
      "Type": "package",
      "Release": "bullseye",
      "Package": "pytorch",
      "Kind": "postponed",
      "Description": "Minor issue; DoS"
    },
    {
      "Original": "NOTE: https://github.com/pytorch/pytorch/issues/150835",
      "Type": "NOTE",
      "Description": "https://github.com/pytorch/pytorch/issues/150835"
    },
    {
      "Original": "NOTE: https://github.com/pytorch/pytorch/pull/150981",
      "Type": "NOTE",
      "Description": "https://github.com/pytorch/pytorch/pull/150981"
    },
    {
      "Original": "NOTE: https://github.com/pytorch/pytorch/commit/01f226bfb8f2c343f5c614a6bbf685d91160f3af (v2.8.0-rc1)",
      "Type": "NOTE",
      "Description": "https://github.com/pytorch/pytorch/commit/01f226bfb8f2c343f5c614a6bbf685d91160f3af (v2.8.0-rc1)"
    }
  ]
}