{
  "Header": {
    "Original": "CVE-2025-59681 (An issue was discovered in Django 4.2 before 4.2.25, 5.1 before 5.1.13 ...)",
    "ID": "CVE-2025-59681",
    "Description": "(An issue was discovered in Django 4.2 before 4.2.25, 5.1 before 5.1.13 ...)"
  },
  "Annotations": [
    {
      "Original": "- python-django 3:4.2.25-1 (bug #1116979)",
      "Type": "package",
      "Package": "python-django",
      "Kind": "fixed",
      "Version": "3:4.2.25-1",
      "BugNo": 1116979
    },
    {
      "Original": "NOTE: https://www.djangoproject.com/weblog/2025/oct/01/security-releases/",
      "Type": "NOTE",
      "Description": "https://www.djangoproject.com/weblog/2025/oct/01/security-releases/"
    },
    {
      "Original": "NOTE: https://github.com/django/django/commit/38d9ef8c7b5cb6ef51b933e51a20e0e0063f33d5 (4.2.25)",
      "Type": "NOTE",
      "Description": "https://github.com/django/django/commit/38d9ef8c7b5cb6ef51b933e51a20e0e0063f33d5 (4.2.25)"
    }
  ]
}